Workbook
Name Slicer_Address: #N/A
Name Slicer_Consulted_By: #N/A
Name Slicer_Visit_Month: #N/A

Sheet raw data
A1: Patient ID | B1: Patient Name | C1: Gender | D1: Age | E1: Visit Date | F1: Address | G1: Consulted By | H1: diagnosis | I1: Treatment | J1: icd10 code | K1: Dental Camp | L1: X-Ray Done | M1: Patient Type | N1: Revenue | O1: Treatment Cost | P1: X-Ray Cost | Q1: OPD Cost | R1: Lab Charges | S1: Discount | T1: Total Paid | U1: Due | V1: Profit | W1: Payment Method | X1: Visit Month
A2: MLPT00001 | B2: Ngozi Okoro | C2: Female | D2: 54 | E2: 44958 | F2: Janakpuri | G2: Dr. Kajal | H2: =INDEX(Table1[Diagnosis],MATCH(I2,'codeand diagnosis'!$A$2:$A$11,0)) -> Gingivitis | I2: Cleaning | J2: =INDEX(Table1[ICD-10 Code],MATCH(Table2[[#This Row],[Treatment]],Table1[Treatment Type],0)) -> K05.10 | K2: No | L2: No | M2: First Visit | N2: =Table2[[#This Row],[Total Paid]]+Table2[[#This Row],[Due]] -> 411 | O2: 411 | P2: 0 | Q2: 0 | R2: 0 | S2: 0 | T2: 411 | U2: 0 | V2: 411 | W2: Online Transfer | X2: 2023-01
A3: MLPT00002 | B3: Chinedu Eze | C3: Male | D3: 73 | E3: 44958 | F3: Vikas Puri | G3: Dr. Karan | H3: =INDEX(Table1[Diagnosis],MATCH(I3,'codeand diagnosis'!$A$2:$A$11,0)) -> Dental examination with radiology | I3: OPD + X-Ray | J3: =INDEX(Table1[ICD-10 Code],MATCH(Table2[[#This Row],[Treatment]],Table1[Treatment Type],0)) -> Z01.2 | K3: No | L3: Yes | M3: First Visit | N3: =Table2[[#This Row],[Total Paid]]+Table2[[#This Row],[Due]] -> 350 | O3: 0 | P3: 150 | Q3: 200 | R3: 0 | S3: 0 | T3: 350 | U3: 0 | V3: 350 | W3: Online Transfer | X3: 2023-01
A4: MLPT00003 | B4: Fatima Bello | C4: Female | D4: 57 | E4: 44986 | F4: Vikas Puri | G4: Dr. Karan | H4: =INDEX(Table1[Diagnosis],MATCH(I4,'codeand diagnosis'!$A$2:$A$11,0)) -> Dental caries | I4: Filling | J4: =INDEX(Table1[ICD-10 Code],MATCH(Table2[[#This Row],[Treatment]],Table1[Treatment Type],0)) -> K02.9 | K4: No | L4: No | M4: First Visit | N4: =Table2[[#This Row],[Total Paid]]+Table2[[#This Row],[Due]] -> 1068 | O4: 1068 | P4: 0 | Q4: 0 | R4: 0 | S4: 0 | T4: 1068 | U4: 0 | V4: 1068 | W4: Cash | X4: 2023-01
A5: MLPT00004 | B5: Emeka Nwafor | C5: Male | D5: 73 | E5: 44986 | F5: Vikas Puri | G5: Dr. Karan | H5: =INDEX(Table1[Diagnosis],MATCH(I5,'codeand diagnosis'!$A$2:$A$11,0)) -> Dental examination | I5: OPD | J5: =INDEX(Table1[ICD-10 Code],MATCH(Table2[[#This Row],[Treatment]],Table1[Treatment Type],0)) -> Z01.2 | K5: No | L5: No | M5: Referral | N5: =Table2[[#This Row],[Total Paid]]+Table2[[#This Row],[Due]] -> 120 | O5: 0 | P5: 0 | Q5: 200 | R5: 0 | S5: 80 | T5: 120 | U5: 0 | V5: 120 | W5: Card | X5: 2023-01
A6: MLPT00005 | B6: Adewale Adeyemi | C6: Male | D6: 16 | E6: 44986 | F6: Tilak Nagar | G6: Dr. Karan | H6: =INDEX(Table1[Diagnosis],MATCH(I6,'codeand diagnosis'!$A$2:$A$11,0)) -> Dental examination | I6: OPD | J6: =INDEX(Table1[ICD-10 Code],MATCH(Table2[[#This Row],[Treatment]],Table1[Treatment Type],0)) -> Z01.2 | K6: No | L6: No | M6: First Visit | N6: =Table2[[#This Row],[Total Paid]]+Table2[[#This Row],[Due]] -> 200 | O6: 0 | P6: 0 | Q6: 200 | R6: 0 | S6: 0 | T6: 200 | U6: 0 | V6: 200 | W6: UPI | X6: 2023-01
A7: MLPT00006 | B7: Jagdish Prasad | C7: Male | D7: 57 | E7: 45017 | F7: Paschim Vihar | G7: Dr. Kajal | H7: =INDEX(Table1[Diagnosis],MATCH(I7,'codeand diagnosis'!$A$2:$A$11,0)) -> Cosmetic procedure | I7: Bleaching | J7: =INDEX(Table1[ICD-10 Code],MATCH(Table2[[#This Row],[Treatment]],Table1[Treatment Type],0)) -> Z41.1 | K7: No | L7: Yes | M7: First Visit | N7: =Table2[[#This Row],[Total Paid]]+Table2[[#This Row],[Due]] -> 1602 | O7: 1602 | P7: 0 | Q7: 0 | R7: 0 | S7: 0 | T7: 1602 | U7: 0 | V7: 1602 | W7: Cash | X7: 2023-01
A8: MLPT00007 | B8: Aisha Khan | C8: Female | D8: 67 | E8: 45017 | F8: Tilak Nagar | G8: Dr. Kajal | H8: =INDEX(Table1[Diagnosis],MATCH(I8,'codeand diagnosis'!$A$2:$A$11,0)) -> Cosmetic procedure | I8: Bleaching | J8: =INDEX(Table1[ICD-10 Code],MATCH(Table2[[#This Row],[Treatment]],Table1[Treatment Type],0)) -> Z41.1 | K8: No | L8: Yes | M8: First Visit | N8: =Table2[[#This Row],[Total Paid]]+Table2[[#This Row],[Due]] -> 1653 | O8: 1653 | P8: 0 | Q8: 0 | R8: 0 | S8: 0 | T8: 1653 | U8: 0 | V8: 1653 | W8: UPI | X8: 2023-01
A9: MLPT00008 | B9: Raghav Singh | C9: Male | D9: 67 | E9: 45047 | F9: Hari Nagar | G9: Dr. Karan | H9: =INDEX(Table1[Diagnosis],MATCH(I9,'codeand diagnosis'!$A$2:$A$11,0)) -> Dental examination with radiology | I9: OPD + X-Ray | J9: =INDEX(Table1[ICD-10 Code],MATCH(Table2[[#This Row],[Treatment]],Table1[Treatment Type],0)) -> Z01.2 | K9: No | L9: Yes | M9: Walk-in | N9: =Table2[[#This Row],[Total Paid]]+Table2[[#This Row],[Due]] -> 350 | O9: 0 | P9: 150 | Q9: 200 | R9: 0 | S9: 0 | T9: 350 | U9: 0 | V9: 350 | W9: Cash | X9: 2023-01
A10: MLPT00009 | B10: Naina Gupta | C10: Female | D10: 13 | E10: 45047 | F10: Paschim Vihar | G10: Dr. Kajal | H10: =INDEX(Table1[Diagnosis],MATCH(I10,'codeand diagnosis'!$A$2:$A$11,0)) -> Dental examination | I10: OPD | J10: =INDEX(Table1[ICD-10 Code],MATCH(Table2[[#This Row],[Treatment]],Table1[Treatment Type],0)) -> Z01.2 | K10: No | L10: No | M10: First Visit | N10: =Table2[[#This Row],[Total Paid]]+Table2[[#This Row],[Due]] -> 200 | O10: 0 | P10: 0 | Q10: 200 | R10: 0 | S10: 0 | T10: 200 | U10: 0 | V10: 200 | W10: Online Transfer | X10: 2023-01
A11: MLPT00010 | B11: Poonam Devi | C11: Female | D11: 30 | E11: 45078 | F11: Tilak Nagar | G11: Dr. Kajal | H11: =INDEX(Table1[Diagnosis],MATCH(I11,'codeand diagnosis'!$A$2:$A$11,0)) -> Dental examination with radiology | I11: OPD + X-Ray | J11: =INDEX(Table1[ICD-10 Code],MATCH(Table2[[#This Row],[Treatment]],Table1[Treatment Type],0)) -> Z01.2 | K11: No | L11: Yes | M11: First Visit | N11: =Table2[[#This Row],[Total Paid]]+Table2[[#This Row],[Due]] -> 210 | O11: 0 | P11: 150 | Q11: 200 | R11: 0 | S11: 140 | T11: 210 | U11: 0 | V11: 210 | W11: Cash | X11: 2023-01
A12: MLPT00011 | B12: Kajal Singh | C12: Female | D12: 80 | E12: 45078 | F12: Tilak Nagar | G12: Dr. Karan | H12: =INDEX(Table1[Diagnosis],MATCH(I12,'codeand diagnosis'!$A$2:$A$11,0)) -> Loss of teeth | I12: Extraction | J12: =INDEX(Table1[ICD-10 Code],MATCH(Table2[[#This Row],[Treatment]],Table1[Treatment Type],0)) -> K08.1 | K12: No | L12: Yes | M12: Walk-in | N12: =Table2[[#This Row],[Total Paid]]+Table2[[#This Row],[Due]] -> 333 | O12: 533 | P12: 0 | Q12: 0 | R12: 0 | S12: 200 | T12: 333 | U12: 0 | V12: 333 | W12: UPI | X12: 2023-01
A13: MLPT00012 | B13: Gia Patel | C13: Female | D13: 73 | E13: 45108 | F13: Tilak Nagar | G13: Dr. Kajal | H13: =INDEX(Table1[Diagnosis],MATCH(I13,'codeand diagnosis'!$A$2:$A$11,0)) -> Dental examination | I13: OPD | J13: =INDEX(Table1[ICD-10 Code],MATCH(Table2[[#This Row],[Treatment]],Table1[Treatment Type],0)) -> Z01.2 | K13: No | L13: No | M13: Walk-in | N13: =Table2[[#This Row],[Total Paid]]+Table2[[#This Row],[Due]] -> 200 | O13: 0 | P13: 0 | Q13: 200 | R13: 0 | S13: 0 | T13: 200 | U13: 0 | V13: 200 | W13: Cash | X13: 2023-01
... A20: MLPT00019 | B20: Rishi Yadav | C20: Male | D20: 62 | E20: 45261 | F20: Tilak Nagar | G20: Dr. Kajal | H20: =INDEX(Table1[Diagnosis],MATCH(I20,'codeand diagnosis'!$A$2:$A$11,0)) -> Dental examination with radiology | I20: OPD + X-Ray | J20: =INDEX(Table1[ICD-10 Code],MATCH(Table2[[#This Row],[Treatment]],Table1[Treatment Type],0)) -> Z01.2 | K20: No | L20: Yes | M20: First Visit | N20: =Table2[[#This Row],[Total Paid]]+Table2[[#This Row],[Due]] -> 210 | O20: 0 | P20: 150 | Q20: 200 | R20: 0 | S20: 140 | T20: 210 | U20: 0 | V20: 210 | W20: Online Transfer | X20: 2023-01
A21: MLPT00020 | B21: Uday Singh | C21: Male | D21: 73 | E21: 13-01-2023 | F21: Chander Vihar | G21: Dr. Kajal | H21: =INDEX(Table1[Diagnosis],MATCH(I21,'codeand diagnosis'!$A$2:$A$11,0)) -> Malocclusion | I21: Braces | J21: =INDEX(Table1[ICD-10 Code],MATCH(Table2[[#This Row],[Treatment]],Table1[Treatment Type],0)) -> K07.4 | K21: No | L21: No | M21: First Visit | N21: =Table2[[#This Row],[Total Paid]]+Table2[[#This Row],[Due]] -> 15253 | O21: 16753 | P21: 0 | Q21: 0 | R21: 3780 | S21: 1500 | T21: 15253 | U21: 0 | V21: 11473 | W21: Online Transfer | X21: 2023-01
A22: MLPT00021 | B22: Ronit Sharma | C22: Male | D22: 68 | E22: 13-01-2023 | F22: Punjabi Bagh | G22: Dr. Kajal | H22: =INDEX(Table1[Diagnosis],MATCH(I22,'codeand diagnosis'!$A$2:$A$11,0)) -> Dental examination | I22: OPD | J22: =INDEX(Table1[ICD-10 Code],MATCH(Table2[[#This Row],[Treatment]],Table1[Treatment Type],0)) -> Z01.2 | K22: No | L22: No | M22: First Visit | N22: =Table2[[#This Row],[Total Paid]]+Table2[[#This Row],[Due]] -> 120 | O22: 0 | P22: 0 | Q22: 200 | R22: 0 | S22: 80 | T22: 120 | U22: 0 | V22: 120 | W22: Card | X22: 2023-01
A23: MLPT00022 | B23: Suhani Yadav | C23: Female | D23: 47 | E23: 14-01-2023 | F23: Tilak Nagar | G23: Dr. Karan | H23: =INDEX(Table1[Diagnosis],MATCH(I23,'codeand diagnosis'!$A$2:$A$11,0)) -> Dental examination with radiology | I23: OPD + X-Ray | J23: =INDEX(Table1[ICD-10 Code],MATCH(Table2[[#This Row],[Treatment]],Table1[Treatment Type],0)) -> Z01.2 | K23: No | L23: Yes | M23: Referral | N23: =Table2[[#This Row],[Total Paid]]+Table2[[#This Row],[Due]] -> 250 | O23: 0 | P23: 150 | Q23: 200 | R23: 0 | S23: 100 | T23: 250 | U23: 0 | V23: 250 | W23: Card | X23: 2023-01
A24: MLPT00023 | B24: Suhani Yadav | C24: Female | D24: 67 | E24: 14-01-2023 | F24: Chander Vihar | G24: Dr. Karan | H24: =INDEX(Table1[Diagnosis],MATCH(I24,'codeand diagnosis'!$A$2:$A$11,0)) -> Gingivitis | I24: Cleaning | J24: =INDEX(Table1[ICD-10 Code],MATCH(Table2[[#This Row],[Treatment]],Table1[Treatment Type],0)) -> K05.10 | K24: No | L24: No | M24: First Visit | N24: =Table2[[#This Row],[Total Paid]]+Table2[[#This Row],[Due]] -> 397.2 | O24: 662 | P24: 0 | Q24: 0 | R24: 0 | S24: 264.8 | T24: 397.2 | U24: 0 | V24: 397.2 | W24: Card | X24: 2023-01
A25: MLPT00024 | B25: Anaya Gupta | C25: Female | D25: 45 | E25: 14-01-2023 | F25: Vikas Puri | G25: Dr. Kajal | H25: =INDEX(Table1[Diagnosis],MATCH(I25,'codeand diagnosis'!$A$2:$A$11,0)) -> Dental examination | I25: OPD | J25: =INDEX(Table1[ICD-10 Code],MATCH(Table2[[#This Row],[Treatment]],Table1[Treatment Type],0)) -> Z01.2 | K25: No | L25: No | M25: First Visit | N25: =Table2[[#This Row],[Total Paid]]+Table2[[#This Row],[Due]] -> 200 | O25: 0 | P25: 0 | Q25: 200 | R25: 0 | S25: 0 | T25: 200 | U25: 0 | V25: 200 | W25: Card | X25: 2023-01
A26: MLPT00025 | B26: Kabir Singh | C26: Male | D26: 23 | E26: 15-01-2023 | F26: Tilak Nagar | G26: Dr. Kajal | H26: =INDEX(Table1[Diagnosis],MATCH(I26,'codeand diagnosis'!$A$2:$A$11,0)) -> Dental examination | I26: OPD | J26: =INDEX(Table1[ICD-10 Code],MATCH(Table2[[#This Row],[Treatment]],Table1[Treatment Type],0)) -> Z01.2 | K26: No | L26: No | M26: First Visit | N26: =Table2[[#This Row],[Total Paid]]+Table2[[#This Row],[Due]] -> 200 | O26: 0 | P26: 0 | Q26: 200 | R26: 0 | S26: 0 | T26: 200 | U26: 0 | V26: 200 | W26: Cash | X26: 2023-01
A27: MLPT00026 | B27: Arnav Gupta | C27: Male | D27: 72 | E27: 15-01-2023 | F27: Uttam Nagar | G27: Dr. Kajal | H27: =INDEX(Table1[Diagnosis],MATCH(I27,'codeand diagnosis'!$A$2:$A$11,0)) -> Dental examination with radiology | I27: OPD + X-Ray | J27: =INDEX(Table1[ICD-10 Code],MATCH(Table2[[#This Row],[Treatment]],Table1[Treatment Type],0)) -> Z01.2 | K27: No | L27: Yes | M27: First Visit | N27: =Table2[[#This Row],[Total Paid]]+Table2[[#This Row],[Due]] -> 350 | O27: 0 | P27: 150 | Q27: 200 | R27: 0 | S27: 0 | T27: 350 | U27: 0 | V27: 350 | W27: Card | X27: 2023-01
A28: MLPT00027 | B28: Vanya Gupta | C28: Female | D28: 70 | E28: 16-01-2023 | F28: Vikas Puri | G28: Dr. Kajal | H28: =INDEX(Table1[Diagnosis],MATCH(I28,'codeand diagnosis'!$A$2:$A$11,0)) -> Dental examination with radiology | I28: OPD + X-Ray | J28: =INDEX(Table1[ICD-10 Code],MATCH(Table2[[#This Row],[Treatment]],Table1[Treatment Type],0)) -> Z01.2 | K28: No | L28: Yes | M28: First Visit | N28: =Table2[[#This Row],[Total Paid]]+Table2[[#This Row],[Due]] -> 350 | O28: 0 | P28: 150 | Q28: 200 | R28: 0 | S28: 0 | T28: 350 | U28: 0 | V28: 350 | W28: Cash | X28: 2023-01
A29: MLPT00028 | B29: Pranav Kumar | C29: Male | D29: 47 | E29: 17-01-2023 | F29: Chander Vihar | G29: Dr. Kajal | H29: =INDEX(Table1[Diagnosis],MATCH(I29,'codeand diagnosis'!$A$2:$A$11,0)) -> Pulpitis | I29: RCT | J29: =INDEX(Table1[ICD-10 Code],MATCH(Table2[[#This Row],[Treatment]],Table1[Treatment Type],0)) -> K04.0 | K29: No | L29: No | M29: First Visit | N29: =Table2[[#This Row],[Total Paid]]+Table2[[#This Row],[Due]] -> 3658 | O29: 3658 | P29: 0 | Q29: 0 | R29: 0 | S29: 0 | T29: 3658 | U29: 0 | V29: 3658 | W29: Cash | X29: 2023-01
A30: MLPT00029 | B30: Uma Sharma | C30: Female | D30: 35 | E30: 17-01-2023 | F30: Hari Nagar | G30: Dr. Karan | H30: =INDEX(Table1[Diagnosis],MATCH(I30,'codeand diagnosis'!$A$2:$A$11,0)) -> Loss of teeth | I30: Extraction | J30: =INDEX(Table1[ICD-10 Code],MATCH(Table2[[#This Row],[Treatment]],Table1[Treatment Type],0)) -> K08.1 | K30: No | L30: Yes | M30: First Visit | N30: =Table2[[#This Row],[Total Paid]]+Table2[[#This Row],[Due]] -> 505 | O30: 505 | P30: 0 | Q30: 0 | R30: 0 | S30: 0 | T30: 505 | U30: 0 | V30: 505 | W30: Online Transfer | X30: 2023-01
A31: MLPT00030 | B31: Riya Kumar | C31: Female | D31: 49 | E31: 18-01-2023 | F31: Tilak Nagar | G31: Dr. Karan | H31: =INDEX(Table1[Diagnosis],MATCH(I31,'codeand diagnosis'!$A$2:$A$11,0)) -> Dental caries | I31: Filling | J31: =INDEX(Table1[ICD-10 Code],MATCH(Table2[[#This Row],[Treatment]],Table1[Treatment Type],0)) -> K02.9 | K31: No | L31: Yes | M31: First Visit | N31: =Table2[[#This Row],[Total Paid]]+Table2[[#This Row],[Due]] -> 621 | O31: 1035 | P31: 0 | Q31: 0 | R31: 0 | S31: 414 | T31: 621 | U31: 0 | V31: 621 | W31: UPI | X31: 2023-01
A32: MLPT00031 | B32: Siya Verma | C32: Female | D32: 55 | E32: 19-01-2023 | F32: Janakpuri | G32: Dr. Karan | H32: =INDEX(Table1[Diagnosis],MATCH(I32,'codeand diagnosis'!$A$2:$A$11,0)) -> Dental caries | I32: Filling | J32: =INDEX(Table1[ICD-10 Code],MATCH(Table2[[#This Row],[Treatment]],Table1[Treatment Type],0)) -> K02.9 | K32: No | L32: No | M32: First Visit | N32: =Table2[[#This Row],[Total Paid]]+Table2[[#This Row],[Due]] -> 1048 | O32: 1048 | P32: 0 | Q32: 0 | R32: 0 | S32: 0 | T32: 1048 | U32: 0 | V32: 1048 | W32: UPI | X32: 2023-01
... A50: MLPT00049 | B50: Urvi Sharma | C50: Female | D50: 64 | E50: 31-01-2023 | F50: Tilak Nagar | G50: Dr. Karan | H50: =INDEX(Table1[Diagnosis],MATCH(I50,'codeand diagnosis'!$A$2:$A$11,0)) -> Dental examination | I50: OPD | J50: =INDEX(Table1[ICD-10 Code],MATCH(Table2[[#This Row],[Treatment]],Table1[Treatment Type],0)) -> Z01.2 | K50: No | L50: No | M50: First Visit | N50: =Table2[[#This Row],[Total Paid]]+Table2[[#This Row],[Due]] -> 200 | O50: 0 | P50: 0 | Q50: 200 | R50: 0 | S50: 0 | T50: 200 | U50: 0 | V50: 200 | W50: UPI | X50: 2023-01
A51: MLPT00050 | B51: Kiara Jain | C51: Female | D51: 6 | E51: 44928 | F51: Tilak Nagar | G51: Dr. Kajal | H51: =INDEX(Table1[Diagnosis],MATCH(I51,'codeand diagnosis'!$A$2:$A$11,0)) -> Malocclusion | I51: Braces | J51: =INDEX(Table1[ICD-10 Code],MATCH(Table2[[#This Row],[Treatment]],Table1[Treatment Type],0)) -> K07.4 | K51: No | L51: Yes | M51: Walk-in | N51: =Table2[[#This Row],[Total Paid]]+Table2[[#This Row],[Due]] -> 12112 | O51: 12112 | P51: 0 | Q51: 0 | R51: 3320 | S51: 0 | T51: 12112 | U51: 0 | V51: 8792 | W51: UPI | X51: 2023-02
A52: MLPT00051 | B52: Hitesh Gupta | C52: Male | D52: 45 | E52: 44959 | F52: Tilak Nagar | G52: Dr. Kajal | H52: =INDEX(Table1[Diagnosis],MATCH(I52,'codeand diagnosis'!$A$2:$A$11,0)) -> Missing teeth | I52: Implants | J52: =INDEX(Table1[ICD-10 Code],MATCH(Table2[[#This Row],[Treatment]],Table1[Treatment Type],0)) -> K08.1 | K52: No | L52: Yes | M52: First Visit | N52: =Table2[[#This Row],[Total Paid]]+Table2[[#This Row],[Due]] -> 27115 | O52: 27115 | P52: 0 | Q52: 0 | R52: 9160 | S52: 0 | T52: 27115 | U52: 0 | V52: 17955 | W52: UPI | X52: 2023-02
A53: MLPT00052 | B53: Poonam Devi | C53: Female | D53: 5 | E53: 44959 | F53: Chander Vihar | G53: Dr. Kajal | H53: =INDEX(Table1[Diagnosis],MATCH(I53,'codeand diagnosis'!$A$2:$A$11,0)) -> Dental examination with radiology | I53: OPD + X-Ray | J53: =INDEX(Table1[ICD-10 Code],MATCH(Table2[[#This Row],[Treatment]],Table1[Treatment Type],0)) -> Z01.2 | K53: No | L53: Yes | M53: First Visit | N53: =Table2[[#This Row],[Total Paid]]+Table2[[#This Row],[Due]] -> 350 | O53: 0 | P53: 150 | Q53: 200 | R53: 0 | S53: 0 | T53: 350 | U53: 0 | V53: 350 | W53: Online Transfer | X53: 2023-02
A54: MLPT00053 | B54: Pranav Kumar | C54: Male | D54: 33 | E54: 44959 | F54: Vikas Puri | G54: Dr. Karan | H54: =INDEX(Table1[Diagnosis],MATCH(I54,'codeand diagnosis'!$A$2:$A$11,0)) -> Retained dental root | I54: Crown | J54: =INDEX(Table1[ICD-10 Code],MATCH(Table2[[#This Row],[Treatment]],Table1[Treatment Type],0)) -> K08.3 | K54: No | L54: No | M54: First Visit | N54: =Table2[[#This Row],[Total Paid]]+Table2[[#This Row],[Due]] -> 3300 | O54: 3300 | P54: 0 | Q54: 0 | R54: 890 | S54: 0 | T54: 3300 | U54: 0 | V54: 2410 | W54: UPI | X54: 2023-02
A55: MLPT00054 | B55: Nikita Sharma | C55: Female | D55: 54 | E55: 44987 | F55: Fateh Nagar | G55: Dr. Karan | H55: =INDEX(Table1[Diagnosis],MATCH(I55,'codeand diagnosis'!$A$2:$A$11,0)) -> Gingivitis | I55: Cleaning | J55: =INDEX(Table1[ICD-10 Code],MATCH(Table2[[#This Row],[Treatment]],Table1[Treatment Type],0)) -> K05.10 | K55: No | L55: Yes | M55: Referral | N55: =Table2[[#This Row],[Total Paid]]+Table2[[#This Row],[Due]] -> 689 | O55: 689 | P55: 0 | Q55: 0 | R55: 0 | S55: 0 | T55: 689 | U55: 0 | V55: 689 | W55: UPI | X55: 2023-02
A56: MLPT00055 | B56: Aarav Sharma | C56: Male | D56: 72 | E56: 44987 | F56: Hari Nagar | G56: Dr. Kajal | H56: =INDEX(Table1[Diagnosis],MATCH(I56,'codeand diagnosis'!$A$2:$A$11,0)) -> Dental examination | I56: OPD | J56: =INDEX(Table1[ICD-10 Code],MATCH(Table2[[#This Row],[Treatment]],Table1[Treatment Type],0)) -> Z01.2 | K56: No | L56: No | M56: Referral | N56: =Table2[[#This Row],[Total Paid]]+Table2[[#This Row],[Due]] -> 200 | O56: 0 | P56: 0 | Q56: 200 | R56: 0 | S56: 0 | T56: 200 | U56: 0 | V56: 200 | W56: Online Transfer | X56: 2023-02
A57: MLPT00056 | B57: Shalini Jain | C57: Female | D57: 27 | E57: 45018 | F57: Chander Vihar | G57: Dr. Kajal | H57: =INDEX(Table1[Diagnosis],MATCH(I57,'codeand diagnosis'!$A$2:$A$11,0)) -> Dental examination with radiology | I57: OPD + X-Ray | J57: =INDEX(Table1[ICD-10 Code],MATCH(Table2[[#This Row],[Treatment]],Table1[Treatment Type],0)) -> Z01.2 | K57: No | L57: Yes | M57: Walk-in | N57: =Table2[[#This Row],[Total Paid]]+Table2[[#This Row],[Due]] -> 210 | O57: 0 | P57: 150 | Q57: 200 | R57: 0 | S57: 140 | T57: 210 | U57: 0 | V57: 210 | W57: UPI | X57: 2023-02
A58: MLPT00057 | B58: Aditi Sharma | C58: Female | D58: 46 | E58: 45018 | F58: Chander Vihar | G58: Dr. Kajal | H58: =INDEX(Table1[Diagnosis],MATCH(I58,'codeand diagnosis'!$A$2:$A$11,0)) -> Gingivitis | I58: Cleaning | J58: =INDEX(Table1[ICD-10 Code],MATCH(Table2[[#This Row],[Treatment]],Table1[Treatment Type],0)) -> K05.10 | K58: No | L58: No | M58: First Visit | N58: =Table2[[#This Row],[Total Paid]]+Table2[[#This Row],[Due]] -> 417 | O58: 417 | P58: 0 | Q58: 0 | R58: 0 | S58: 0 | T58: 417 | U58: 0 | V58: 417 | W58: Cash | X58: 2023-02
A59: MLPT00058 | B59: Bhavya Jain | C59: Female | D59: 68 | E59: 45109 | F59: Rajouri Garden | G59: Dr. Kajal | H59: =INDEX(Table1[Diagnosis],MATCH(I59,'codeand diagnosis'!$A$2:$A$11,0)) -> Gingivitis | I59: Cleaning | J59: =INDEX(Table1[ICD-10 Code],MATCH(Table2[[#This Row],[Treatment]],Table1[Treatment Type],0)) -> K05.10 | K59: No | L59: Yes | M59: First Visit | N59: =Table2[[#This Row],[Total Paid]]+Table2[[#This Row],[Due]] -> 555 | O59: 555 | P59: 0 | Q59: 0 | R59: 0 | S59: 0 | T59: 555 | U59: 0 | V59: 555 | W59: UPI | X59: 2023-02
A60: MLPT00059 | B60: Misha Sharma | C60: Female | D60: 62 | E60: 45109 | F60: Vikas Puri | G60: Dr. Kajal | H60: =INDEX(Table1[Diagnosis],MATCH(I60,'codeand diagnosis'!$A$2:$A$11,0)) -> Dental examination | I60: OPD | J60: =INDEX(Table1[ICD-10 Code],MATCH(Table2[[#This Row],[Treatment]],Table1[Treatment Type],0)) -> Z01.2 | K60: No | L60: No | M60: First Visit | N60: =Table2[[#This Row],[Total Paid]]+Table2[[#This Row],[Due]] -> 120 | O60: 0 | P60: 0 | Q60: 200 | R60: 0 | S60: 80 | T60: 120 | U60: 0 | V60: 120 | W60: UPI | X60: 2023-02
A61: MLPT00060 | B61: Akshat Kumar | C61: Male | D61: 45 | E61: 45140 | F61: Tilak Nagar | G61: Dr. Kajal | H61: =INDEX(Table1[Diagnosis],MATCH(I61,'codeand diagnosis'!$A$2:$A$11,0)) -> Dental examination | I61: OPD | J61: =INDEX(Table1[ICD-10 Code],MATCH(Table2[[#This Row],[Treatment]],Table1[Treatment Type],0)) -> Z01.2 | K61: No | L61: No | M61: First Visit | N61: =Table2[[#This Row],[Total Paid]]+Table2[[#This Row],[Due]] -> 200 | O61: 0 | P61: 0 | Q61: 200 | R61: 0 | S61: 0 | T61: 200 | U61: 0 | V61: 200 | W61: Cash | X61: 2023-02
A62: MLPT00061 | B62: Ronit Sharma | C62: Male | D62: 52 | E62: 45140 | F62: Uttam Nagar | G62: Dr. Kajal | H62: =INDEX(Table1[Diagnosis],MATCH(I62,'codeand diagnosis'!$A$2:$A$11,0)) -> Malocclusion | I62: Braces | J62: =INDEX(Table1[ICD-10 Code],MATCH(Table2[[#This Row],[Treatment]],Table1[Treatment Type],0)) -> K07.4 | K62: No | L62: Yes | M62: First Visit | N62: =Table2[[#This Row],[Total Paid]]+Table2[[#This Row],[Due]] -> 11805 | O62: 13305 | P62: 0 | Q62: 0 | R62: 2120 | S62: 1500 | T62: 11805 | U62: 0 | V62: 9685 | W62: UPI | X62: 2023-02
... A66: MLPT00065 | B66: Sahil Gupta | C66: Male | D66: 16 | E66: 45201 | F66: Tilak Nagar | G66: Dr. Karan | H66: =INDEX(Table1[Diagnosis],MATCH(I66,'codeand diagnosis'!$A$2:$A$11,0)) -> Dental examination with radiology | I66: OPD + X-Ray | J66: =INDEX(Table1[ICD-10 Code],MATCH(Table2[[#This Row],[Treatment]],Table1[Treatment Type],0)) -> Z01.2 | K66: No | L66: Yes | M66: First Visit | N66: =Table2[[#This Row],[Total Paid]]+Table2[[#This Row],[Due]] -> 350 | O66: 0 | P66: 150 | Q66: 200 | R66: 0 | S66: 0 | T66: 350 | U66: 0 | V66: 350 | W66: Card | X66: 2023-02
...

Sheet Revenue and financial 
D1: treatment | E1: Profit | F1: treatment | G1: Total Paid | H1: Doctor | I1: Total Paid | J1: Doctor | K1: Profit | L1: Mounth | M1: Total Paid | N1: Mounth | O1: Sum of Profit | Q1: Mounth | R1: Sum of Due
D2: Bleaching | E2: 51398 | F2: Bleaching | G2: 51398 | H2: Dr. Kajal | I2: 1732211.2 | J2: Dr. Kajal | K2: 1336211.2 | L2: 2023-01 | M2: 136975.2 | N2: 2023-01 | O2: 103925.2 | Q2: 2023-01 | R2: 0
D3: Braces | E3: 484343 | F3: Braces | G3: 647933 | H3: Dr. Karan | I3: 163368.6 | J3: Dr. Karan | K3: 139418.6 | L3: 2023-02 | M3: 136843.4 | N3: 2023-02 | O3: 102223.4 | Q3: 2023-02 | R3: 3716
D4: Cleaning | E4: 31776 | F4: Cleaning | G4: 31776 | H4: Grand Total | I4: 1895579.8 | J4: Grand Total | K4: 1475629.8 | L4: 2023-03 | M4: 73510.4 | N4: 2023-03 | O4: 57710.4 | Q4: 2023-03 | R4: 3495
D5: Crown | E5: 46363 | F5: Crown | G5: 70313 | H5: Sum of Due | L5: 2023-04 | M5: 108569.6 | N5: 2023-04 | O5: 82989.6 | Q5: 2023-04 | R5: 0
D6: Extraction | E6: 20877 | F6: Extraction | G6: 20877 | H6: Row Labels | I6: Dr. Kajal | J6: Dr. Karan | K6: Grand Total | L6: 2023-05 | M6: 56856.4 | N6: 2023-05 | O6: 47526.4 | Q6: 2023-05 | R6: 0
D7: Filling | E7: 19103.8 | F7: Filling | G7: 19103.8 | H7: Bleaching | I7: 2338 | K7: 2338 | L7: 2023-06 | M7: 26459.2 | N7: 2023-06 | O7: 23299.2 | Q7: 2023-06 | R7: 844
D8: Implants | E8: 606438 | F8: Implants | G8: 838848 | H8: Braces | I8: 35842 | K8: 35842 | L8: 2023-07 | M8: 84297 | N8: 2023-07 | O8: 66207 | Q8: 2023-07 | R8: 0
D9: OPD | E9: 48100 | F9: OPD | G9: 48100 | H9: Cleaning | I9: 0 | J9: 0 | K9: 0 | L9: 2023-08 | M9: 46295.4 | N9: 2023-08 | O9: 35835.4 | Q9: 2023-08 | R9: 8935
D10: OPD + X-Ray | E10: 90030 | F10: OPD + X-Ray | G10: 90030 | H10: Crown | J10: 1197 | K10: 1197 | L10: 2023-09 | M10: 38989 | N10: 2023-09 | O10: 33409 | Q10: 2023-09 | R10: 2509
D11: RCT | E11: 77201 | F11: RCT | G11: 77201 | H11: Extraction | J11: 0 | K11: 0 | L11: 2023-10 | M11: 50215 | N11: 2023-10 | O11: 43225 | Q11: 2023-10 | R11: 0
D12: Grand Total | E12: 1475629.8 | F12: Grand Total | G12: 1895579.8 | H12: Filling | J12: 0 | K12: 0 | L12: 2023-11 | M12: 38081.2 | N12: 2023-11 | O12: 31171.2 | Q12: 2023-11 | R12: 1666
D13: Sum of Discount | H13: Implants | I13: 21852 | K13: 21852 | L13: 2023-12 | M13: 173873 | N13: 2023-12 | O13: 132393 | Q13: 2023-12 | R13: 0
D14: treatment | E14: Dr. Kajal | F14: Dr. Karan | G14: Grand Total | H14: OPD | I14: 0 | J14: 0 | K14: 0 | L14: 2024-01 | M14: 129080.4 | N14: 2024-01 | O14: 97990.4 | Q14: 2024-01 | R14: 224
D15: Bleaching | E15: 5582 | G15: 5582 | H15: OPD + X-Ray | I15: 0 | J15: 0 | K15: 0 | L15: 2024-02 | M15: 61593 | N15: 2024-02 | O15: 50803 | Q15: 2024-02 | R15: 0
D16: Braces | E16: 11450 | G16: 11450 | H16: RCT | I16: 1552 | K16: 1552 | L16: 2024-03 | M16: 137501 | N16: 2024-03 | O16: 103961 | Q16: 2024-03 | R16: 7309
D17: Cleaning | E17: 2270.8 | F17: 867.2 | G17: 3138 | H17: Grand Total | I17: 61584 | J17: 1197 | K17: 62781 | L17: 2024-04 | M17: 52103.6 | N17: 2024-04 | O17: 42213.6 | Q17: 2024-04 | R17: 863
D18: Crown | F18: 300 | G18: 300 | H18: patient type | I18: Sum of Total Paid | L18: 2024-05 | M18: 32949.6 | N18: 2024-05 | O18: 27999.6 | Q18: 2024-05 | R18: 0
D19: Extraction | F19: 2188 | G19: 2188 | H19: First Visit | I19: 1428923.2 | L19: 2024-06 | M19: 45390 | N19: 2024-06 | O19: 33960 | Q19: 2024-06 | R19: 5821
D20: Filling | F20: 1111.2 | G20: 1111.2 | H20: Referral | I20: 221584.4 | L20: 2024-07 | M20: 76580 | N20: 2024-07 | O20: 60620 | Q20: 2024-07 | R20: 0
D21: Implants | E21: 4700 | G21: 4700 | H21: Walk-in | I21: 245072.2 | L21: 2024-08 | M21: 85032 | N21: 2024-08 | O21: 63812 | Q21: 2024-08 | R21: 17646
D22: OPD | E22: 3930 | F22: 1770 | G22: 5700 | H22: Grand Total | I22: 1895579.8 | L22: 2024-09 | M22: 34883.4 | N22: 2024-09 | O22: 25153.4 | Q22: 2024-09 | R22: 9363
D23: OPD + X-Ray | E23: 7680 | F23: 3490 | G23: 11170 | L23: 2024-10 | M23: 148381 | N23: 2024-10 | O23: 113071 | Q23: 2024-10 | R23: 0
D24: RCT | E24: 2900 | G24: 2900 | L24: 2024-11 | M24: 17501 | N24: 2024-11 | O24: 17501 | Q24: 2024-11 | R24: 0
D25: Grand Total | E25: 38512.8 | F25: 9726.4 | G25: 48239.2 | L25: 2024-12 | M25: 103620 | N25: 2024-12 | O25: 78630 | Q25: 2024-12 | R25: 390
L26: Grand Total | M26: 1895579.8 | N26: Grand Total | O26: 1475629.8 | Q26: Grand Total | R26: 62781

Sheet Dashboard
F1: Dental clinic dashboard
C2: Total REVENUE | G2: patient count | I2: profit | K2: AVG REVENUE
C3: =SUM('raw data'!N:N) -> 1958360.8 | G3: =COUNTA('raw data'!A:A) -> 898 | I3: =SUM('raw data'!V:V) -> 1475629.8 | K3: =C3/24 -> 81598.367
C4: COLLECTION RATE
C5: =SUM(Table2[Total Paid])/Dashboard!C3 -> 0.96794207
W6: =

Sheet Medical analysis 
C1: Row Labels | D1: Count of Patient ID
C2: Cosmetic procedure | D2: 39 | E2: treatment | F2: count
C3: Dental caries | D3: 23 | E3: Bleaching | F3: 39
C4: Dental examination | D4: 305 | E4: Braces | F4: 44
C5: Dental examination with radiology | D5: 308 | E5: Cleaning | F5: 62
C6: Gingivitis | D6: 62 | E6: Crown | F6: 25
C7: Loss of teeth | D7: 30 | E7: Extraction | F7: 30
C8: Malocclusion | D8: 44 | E8: Filling | F8: 23
C9: Missing teeth | D9: 36 | E9: Implants | F9: 36
C10: Pulpitis | D10: 25 | E10: OPD | F10: 305
C11: Retained dental root | D11: 25 | E11: OPD + X-Ray | F11: 308
C12: Grand Total | D12: 897 | E12: RCT | F12: 25
E13: Grand Total | F13: 897

Sheet codeand diagnosis
A1: Treatment Type | B1: ICD-10 Code | C1: Diagnosis
A2: OPD | B2: Z01.2 | C2: Dental examination
A3: OPD + X-Ray | B3: Z01.2 | C3: Dental examination with radiology
A4: Cleaning | B4: K05.10 | C4: Gingivitis
A5: Filling | B5: K02.9 | C5: Dental caries
A6: RCT | B6: K04.0 | C6: Pulpitis
A7: Extraction | B7: K08.1 | C7: Loss of teeth
A8: Crown | B8: K08.3 | C8: Retained dental root
A9: Implants | B9: K08.1 | C9: Missing teeth
A10: Braces | B10: K07.4 | C10: Malocclusion
A11: Bleaching | B11: Z41.1 | C11: Cosmetic procedure

Sheet performance 
A1: Doctors | B1: work load | C1: Row Labels | D1: Sum of Profit | E1: Sum of Due | F1: Sum of Total Paid
A2: Dr. Kajal | B2: 617 | C2: Dr. Kajal | D2: 1336211.2 | E2: 61584 | F2: 1732211.2
A3: Dr. Karan | B3: 280 | C3: Dr. Karan | D3: 139418.6 | E3: 1197 | F3: 163368.6
A4: Grand Total | B4: 897 | C4: Grand Total | D4: 1475629.8 | E4: 62781 | F4: 1895579.8
C5: type of treatment | D5: count of cases
C6: Dr. Kajal | D6: 617
C7: Bleaching | D7: 39
C8: Braces | D8: 44
C9: Cleaning | D9: 42
C10: Implants | D10: 36
C11: OPD | D11: 220
C12: OPD + X-Ray | D12: 211
C13: RCT | D13: 25
C14: Dr. Karan | D14: 280
C15: Cleaning | D15: 20
C16: Crown | D16: 25
C17: Extraction | D17: 30
... C21: Grand Total | D21: 897

Sheet patient analysis
A1: patient type | B1: count of patient | F1: Age | G1: (All)
A2: First Visit | B2: 692
A3: Referral | B3: 129 | F3: Count of Patient | G3: Column Labels
A4: Walk-in | B4: 76 | F4: Row Labels | G4: Bleaching | H4: Braces | I4: Cleaning | J4: Crown | K4: Extraction | L4: Filling | M4: Implants | N4: OPD | O4: OPD + X-Ray | P4: RCT | Q4: Grand Total
A5: Grand Total | B5: 897 | F5: Female | G5: 16 | H5: 23 | I5: 38 | J5: 10 | K5: 14 | L5: 11 | M5: 18 | N5: 140 | O5: 146 | P5: 12 | Q5: 428
F6: Male | G6: 23 | H6: 21 | I6: 24 | J6: 15 | K6: 16 | L6: 12 | M6: 18 | N6: 165 | O6: 162 | P6: 13 | Q6: 469
F7: Grand Total | G7: 39 | H7: 44 | I7: 62 | J7: 25 | K7: 30 | L7: 23 | M7: 36 | N7: 305 | O7: 308 | P7: 25 | Q7: 897
C17: Row Labels | D17: Count of Patient
C18: 2023-01 | D18: 49
C19: 2023-02 | D19: 38
C20: 2023-03 | D20: 34
C21: 2023-04 | D21: 42
C22: 2023-05 | D22: 40
C23: 2023-06 | D23: 36
C24: 2023-07 | D24: 33
C25: 2023-08 | D25: 35
C26: 2023-09 | D26: 32
C27: 2023-10 | D27: 41
C28: 2023-11 | D28: 35
C29: 2023-12 | D29: 45
... C42: Grand Total | D42: 897

Sheet operation
A1: xray | B1: Count of Patient | C1: Sum of X-Ray Cost | D1: Sum of Lab Charges
A2: No | B2: 399 | C2: 46200 | D2: 419950
A3: Yes | B3: 498
A4: Grand Total | B4: 897

Sheet payment analysis
A1: payment method | B1: Sum of Total Paid
A2: Card | B2: 358287
A3: Cash | B3: 569237.8
A4: Online Transfer | B4: 165537.2
A5: UPI | B5: 802517.8
A6: Grand Total | B6: 1895579.8
